Workbook

Sheet Sheet1
A1: 運送委託書 / 運送引取書
I2: 申込日 | J2: 2026年09月29日 (Tue)
A3: 委託者 | B3: 社名 | C3: ●●●● | I3: 担当者 | J3: ●● ●●
I4: TEL | J4: ●● ●●
B5: 住所 | C5: ●●●● | I5: FAX | J5: ●● ●●
I6: 緊急連絡先 | J6: ●● ●●
A7: 引受者 | B7: 社名 | H7: 御中 | I7: 担当者
A11: 積地 | B11: 月日 | G11: 時間
B12: 会社名
B13: 住所
B14: 担当者 | G14: 電話番号
B15: その他
A17: 着地 | B17: 月日 | G17: 時間
B18: 会社名
B19: 住所
B20: 担当者 | G20: 電話番号
B21: その他
A22: メモ
A23: メモ
A26: 車種 | D26: 積荷 | H26: 積荷 | I26: 雑貨
H27: 内容
A29: 積込作業の委託 | C29: 無 ・ 有 | E29: 作業時間(合計 分程度) | I29: 作業詳細( )
A30: 荷卸作業の委託 | C30: 無 ・ 有 | E30: 作業時間(合計 分程度) | I30: 作業詳細( )
A32: 運賃 | C32: 円 | G32: 有料道路利用料(税込み) | I32: 無 ・ 有（ ）
A33: 燃料サーチャージ | C33: 円
A34: 待機料 | C34: 円 | G34: (見込待機時間： 分 30分あたり単価： 円)
A35: 付帯業務料 | C35: 円 | G35: 無 ・ 有 (業務日時・内容： )
A36: ＊本運送委託書の金額は、消費税・地方消費税抜きの金額です。支払期日には法定税率による消費税額・地方消費税額分を加算して支払います。
A38: 締日：末 ・ ( )日 締 | D38: 払日：( 翌 ・ 翌々 ) 月末払 ・ ( )払 | J38: 支払方法：銀行振込
A40: ※車番が決まりましたら返信ファックスをお願いします。(FAX:048-910-9701)
A41: 車番連絡
A42: 実運送会社 | D42: 車種 | F42: 車番 | H42: 氏名 | J42: 携帯番号
A45: 請負階層
A47: 上記実運送会社は、 | D47: 次 | F47: 請負事業者となります。
A48: ＊(株)樋口物流サービスが一次請負事業者として何次請負事業者かお教えください。
A51: ・上記の通り運送を受託します。
B52: 令和 年 月 日
B53: 運送受託者（貨物自動車運送事業者）

Sheet 01_テスト結果一覧
A1: 配車指示書AI PoC テスト結果一覧
A3: 実施件数 | B3: 合格件数 | C3: 不合格件数 | D3: 合格率 | E3: 誤読合計 | F3: 勝手に確定 | G3: 禁止情報誤出力 | H3: 平均総作業時間(分)
A4: =COUNTA(C7:C106) -> 90 | B4: =COUNTIF(Y7:Y106,"合格") -> 0 | C4: =COUNTIF(Y7:Y106,"不合格") -> 0 | D4: =IF(A4=0,"",B4/A4) -> 0 | E4: =SUM(Q7:Q106) -> 0 | F4: =SUM(R7:R106) -> 0 | G4: =SUM(T7:T106) -> 0 | H4: =IFERROR(AVERAGE(N7:N106),"")
A6: No. | B6: 実施日 | C6: ケースID | D6: 試験ID | E6: 原本種別 | F6: 積地エリア | G6: 卸地エリア | H6: 難易度 | I6: 流用元有無 | J6: 新規入力項目数 | K6: AI操作時間(分) | L6: 人の確認時間(分) | M6: 修正時間(分) | N6: 総作業時間(分) | O6: 明確に読取れた項目数 | P6: 要確認項目数 | Q6: 誤読件数 | R6: 勝手に確定した件数 | S6: 積地・卸地順序誤り件数 | T6: 禁止情報誤出力件数 | U6: テンプレート自動入力 | V6: 修正内容 | W6: 判定者 | X6: 配車担当確認 | Y6: 合否 | Z6: 確認メモ | AA6: 処理開始時刻 | AB6: 画像読込開始時刻 | AC6: 画像読込完了時刻 | AD6: 画像読込所要時間(秒) | AE6: 処理完了時刻 | AF6: Excel書込開始時刻 | AG6: PDF出力完了時刻 | AH6: Excel書込・PDF出力所要時間(秒) | AI6: 記載なし項目数 | AJ6: 矛盾項目数 | AK6: AIが人に確認を戻した項目数 | AL6: 読込結果反映状況 | AM6: 読込結果反映メモ | AN6: 対象 | AO6: 帳票／形式 | AP6: 主な確認内容 | AQ6: 合格条件 | AR6: このケースの検証ポイント | AS6: 推奨判定者 | AT6: 不合格となる例 | AU6: 判定基準備考 | AV6: 画像ファイル名
A7: 1 | C7: D001 | D7: T01 | E7: 定型印字帳票 | AN7: 標準印字・定型帳票 | AO7: 貨物配送依頼書 | AP7: 明瞭な印字項目の抽出・欄対応 | AQ7: 明瞭な必須情報の抽出漏れ0件、明瞭な情報の誤入力・誤分類0件。未記載は補完しない。 | AR7: 表形式で明瞭な標準帳票。明瞭な印字項目の抽出・欄対応を中心に検証する。 | AS7: 配車担当＋作成者 | AT7: 明瞭な積地・卸地・日時・数量を誤読／別欄へ誤分類する | AU7: 標準読取のベースライン | AV7: D001.jpg
A8: 2 | C8: D002 | D8: T02 | E8: 劣化FAX | AN8: FAX・スキャン劣化 | AO8: 配送依頼書（FAX） | AP8: かすれ・黒つぶれ・低コントラスト箇所の扱い | AQ8: 判読できる箇所の誤読0件。判読不能箇所の勝手な確定0件。不明は要確認にする。 | AR8: 黒つぶれ・かすれ・走査ノイズが目立つFAX。かすれ・黒つぶれ・低コントラスト箇所の扱いを中心に検証する。 | AS8: 配車担当＋作成者 | AT8: 潰れた電話番号や文字を推測して確定する | AU8: 画像劣化は安全側に倒す | AV8: D002.jpg
A9: 3 | C9: D003 | D9: T03 | E9: 全手書きメモ | AN9: 手書き主体 | AO9: 運送手配メモ | AP9: 手書き情報の抽出・構造化 | AQ9: 明確に読める手書き情報の反映漏れ0件、誤読0件。判読不能は要確認にする。 | AR9: 紙面全体が手書きで、吹き出し状の追記もある。手書き情報の抽出・構造化を中心に検証する。 | AS9: 配車担当＋作成者 | AT9: 読めない手書きを推測する／積地と卸地を取り違える | AU9: 手書きの表現揺れを吸収しつつ原文を保持 | AV9: D003.jpg
A10: 4 | C10: D004 | D10: T07 | E10: メール印刷＋手書き追記 | AN10: 訂正・追記・矛盾 | AO10: 配送依頼メール | AP10: 訂正前後・追記・矛盾情報の優先判断 | AQ10: 明確な訂正後情報の採用漏れ0件。取消線前の値を採用しない。矛盾が残る場合は勝手に決めず要確認へ戻す。 | AR10: メール本文に手書きの時刻・連絡注意等が追加されている。訂正前後・追記・矛盾情報の優先判断を中心に検証する。 | AS10: 配車担当＋作成者 | AT10: 訂正前の数量・時刻を採用／付箋や赤字追記を無視／矛盾する一方を勝手に採用 | AU10: 訂正の意図が不明なら人が最終判断 | AV10: D004.jpg
A11: 5 | C11: D005 | D11: T07 | E11: 定型印字帳票＋手書き訂正 | AN11: 訂正・追記・矛盾 | AO11: 運送指示書 | AP11: 訂正前後・追記・矛盾情報の優先判断 | AQ11: 明確な訂正後情報の採用漏れ0件。取消線前の値を採用しない。矛盾が残る場合は勝手に決めず要確認へ戻す。 | AR11: 積込時刻・数量などに手書き訂正が入っている。訂正前後・追記・矛盾情報の優先判断を中心に検証する。 | AS11: 配車担当＋作成者 | AT11: 訂正前の数量・時刻を採用／付箋や赤字追記を無視／矛盾する一方を勝手に採用 | AU11: 訂正の意図が不明なら人が最終判断 | AV11: D005.jpg
A12: 6 | C12: D006 | D12: T02 | E12: 劣化FAX＋手書き記入 | AN12: FAX・スキャン劣化 | AO12: 運送依頼書（FAX） | AP12: かすれ・黒つぶれ・低コントラスト箇所の扱い | AQ12: 判読できる箇所の誤読0件。判読不能箇所の勝手な確定0件。不明は要確認にする。 | AR12: FAXノイズが強く、手書き記入欄も混在している。かすれ・黒つぶれ・低コントラスト箇所の扱いを中心に検証する。 | AS12: 配車担当＋作成者 | AT12: 潰れた電話番号や文字を推測して確定する | AU12: 画像劣化は安全側に倒す | AV12: D006.jpg
A13: 7 | C13: D007 | D13: T05 | E13: 複数地点ルート表（印字） | AN13: 複数地点・複数案件 | AO13: 配送依頼書（複数地点） | AP13: 地点・案件の順序と日時・荷物の紐付け保持 | AQ13: 地点・案件の欠落0件、順序逆転0件、日時・荷物・担当の紐付け誤り0件。 | AR13: 積込2地点・荷卸2地点が順序付きで記載されている。地点・案件の順序と日時・荷物の紐付け保持を中心に検証する。 | AS13: 配車担当 | AT13: 積地②と卸地①を逆転する／別案件の数量を混在させる | AU13: 順番や紐付けが不明なら要確認 | AV13: D007.jpg
A14: 8 | C14: D008 | D14: T06 | E14: 印字依頼文書 | AN14: 曖昧日時・時間幅 | AO14: 輸送手配依頼文書 | AP14: AM/PM・午前中・頃・まで・以降・時間幅の保持 | AQ14: 日付・曜日・AM/PM誤り0件。条件語・時間幅の欠落0件。曖昧表現を具体時刻へ勝手に変換しない。 | AR14: 『午前9時頃』『午前中』『午後2時まで』等の幅を持つ時刻表現がある。AM/PM・午前中・頃・まで・以降・時間幅の保持を中心に検証する。 | AS14: 配車担当＋作成者 | AT14: 『午前中』『PM』『9時頃』を単一時刻へ確定する | AU14: 原文条件を保持 | AV14: D008.jpg
A15: 9 | C15: D009 | D15: T07 | E15: 印字帳票＋大量手書き追記 | AN15: 訂正・追記・矛盾 | AO15: 運送手配依頼書 | AP15: 訂正前後・追記・矛盾情報の優先判断 | AQ15: 明確な訂正後情報の採用漏れ0件。取消線前の値を採用しない。矛盾が残る場合は勝手に決めず要確認へ戻す。 | AR15: 多数の赤字・青字追記、地図、時刻修正が混在している。訂正前後・追記・矛盾情報の優先判断を中心に検証する。 | AS15: 配車担当＋作成者 | AT15: 訂正前の数量・時刻を採用／付箋や赤字追記を無視／矛盾する一方を勝手に採用 | AU15: 訂正の意図が不明なら人が最終判断 | AV15: D009.jpg
A16: 10 | C16: D010 | D16: T01 | E16: 定型印字帳票 | AN16: 標準印字・定型帳票 | AO16: 運行依頼書 | AP16: 明瞭な印字項目の抽出・欄対応 | AQ16: 明瞭な必須情報の抽出漏れ0件、明瞭な情報の誤入力・誤分類0件。未記載は補完しない。 | AR16: 明瞭な単一積地・単一納品先の標準帳票。明瞭な印字項目の抽出・欄対応を中心に検証する。 | AS16: 配車担当＋作成者 | AT16: 明瞭な積地・卸地・日時・数量を誤読／別欄へ誤分類する | AU16: 標準読取のベースライン | AV16: D010.jpg
A17: 11 | C17: D011 | D17: T01 | E17: 定型印字帳票 | AN17: 標準印字・定型帳票 | AO17: 運送指示書 | AP17: 明瞭な印字項目の抽出・欄対応 | AQ17: 明瞭な必須情報の抽出漏れ0件、明瞭な情報の誤入力・誤分類0件。未記載は補完しない。 | AR17: 明瞭な表形式の標準印字帳票。明瞭な印字項目の抽出・欄対応を中心に検証する。 | AS17: 配車担当＋作成者 | AT17: 明瞭な積地・卸地・日時・数量を誤読／別欄へ誤分類する | AU17: 標準読取のベースライン | AV17: D011.jpg
A18: 12 | C18: D012 | D18: T02 | E18: 劣化FAX | AN18: FAX・スキャン劣化 | AO18: 配送依頼書（FAX） | AP18: かすれ・黒つぶれ・低コントラスト箇所の扱い | AQ18: 判読できる箇所の誤読0件。判読不能箇所の勝手な確定0件。不明は要確認にする。 | AR18: 罫線・文字のかすれとFAXノイズがある。かすれ・黒つぶれ・低コントラスト箇所の扱いを中心に検証する。 | AS18: 配車担当＋作成者 | AT18: 潰れた電話番号や文字を推測して確定する | AU18: 画像劣化は安全側に倒す | AV18: D012.jpg
... A35: 29 | C35: D029 | D35: T09 | E35: 定型印字帳票＋運賃・支払情報 | AN35: 禁止情報混在 | AO35: 輸送依頼書 | AP35: 運賃・支払・金額情報の非転記 | AQ35: 禁止情報誤出力0件。運行に必要な情報だけを抽出し、運賃・支払・単価等を配車指示書へ転記しない。 | AR35: 受注運賃『¥135,000』と支払条件が帳票内に明記されている。運賃・支払・金額情報の非転記を中心に検証する。 | AS35: 配車担当＋社内ルール判定者 | AT35: 運賃・受注金額・支払条件などを運送会社向け指示書へ出力する | AU35: 禁止範囲は運用ルールを優先 | AV35: D029.jpg
A36: 30 | C36: D030 | D36: T10 | E36: 今回案件＋前回実績併記帳票 | N36: =IF(AND(K36<>"",L36<>"",M36<>""),K36+L36+M36,"") | AN36: 今回・過去／参考情報併記 | AO36: 運送依頼書（今回／前回比較） | AP36: 今回情報と過去・参考情報の優先制御 | AQ36: 過去・参考値による今回情報の自動上書き0件。今回欄と参考欄を混在させない。 | AR36: 今回依頼の下に前回実績が別枠で併記されている。今回情報と過去・参考情報の優先制御を中心に検証する。 | AS36: 配車担当＋作成者 | AT36: 前回担当者・数量・時刻を今回欄へ確定する | AU36: 今回原本を優先し、過去情報は候補扱い | AV36: D030.jpg
A37: 31 | C37: D031 | D37: T06 | E37: 全手書きメモ | AN37: 曖昧日時・時間幅 | AO37: 配車メモ | AP37: AM/PM・午前中・頃・まで・以降・時間幅の保持 | AQ37: 日付・曜日・AM/PM誤り0件。条件語・時間幅の欠落0件。曖昧表現を具体時刻へ勝手に変換しない。 | AR37: 『5/12 PM』『14時までに着』という幅・期限表現がある。AM/PM・午前中・頃・まで・以降・時間幅の保持を中心に検証する。 | AS37: 配車担当＋作成者 | AT37: 『午前中』『PM』『9時頃』を単一時刻へ確定する | AU37: 原文条件を保持 | AV37: D031.jpg
A38: 32 | C38: D032 | D38: T01 | E38: FAX送信票（鮮明） | AN38: 標準印字・定型帳票 | AO38: FAX送信票／配車依頼 | AP38: 明瞭な印字項目の抽出・欄対応 | AQ38: 明瞭な必須情報の抽出漏れ0件、明瞭な情報の誤入力・誤分類0件。未記載は補完しない。 | AR38: FAX形式だが文字・表は鮮明で標準項目抽出が中心。明瞭な印字項目の抽出・欄対応を中心に検証する。 | AS38: 配車担当＋作成者 | AT38: 明瞭な積地・卸地・日時・数量を誤読／別欄へ誤分類する | AU38: 標準読取のベースライン | AV38: D032.jpg
A39: 33 | C39: D033 | D39: T06 | E39: 全手書きメモ | N39: =IF(COUNTA(K39:M39)=0,"",SUM(K39:M39)) | AN39: 曖昧日時・時間幅 | AO39: 配車メモ | AP39: AM/PM・午前中・頃・まで・以降・時間幅の保持 | AQ39: 日付・曜日・AM/PM誤り0件。条件語・時間幅の欠落0件。曖昧表現を具体時刻へ勝手に変換しない。 | AR39: 手書き原本に納品『午前中』指定がある。AM/PM・午前中・頃・まで・以降・時間幅の保持を中心に検証する。 | AS39: 配車担当＋作成者 | AT39: 『午前中』『PM』『9時頃』を単一時刻へ確定する | AU39: 原文条件を保持 | AV39: D033.jpg
A40: 34 | C40: D034 | D40: T04 | E40: メール印刷 | AN40: メール・自由文 | AO40: 配送依頼メール | AP40: 文章・メール本文からの項目整理 | AQ40: 明確な必須情報の抽出漏れ0件、積地・卸地・日時・荷物の誤分類0件。 | AR40: メール本文の箇条書きから運送条件を整理する形式。文章・メール本文からの項目整理を中心に検証する。 | AS40: 配車担当＋作成者 | AT40: 文章中の卸地を積地欄へ入れる／担当・日時の紐付けを崩す | AU40: レイアウト非依存 | AV40: D034.jpg
A41: 35 | C41: D035 | D41: T03 | E41: 手書きメモ＋付箋 | AN41: 手書き主体 | AO41: 配車メモ | AP41: 手書き情報の抽出・構造化 | AQ41: 明確に読める手書き情報の反映漏れ0件、誤読0件。判読不能は要確認にする。 | AR41: 手書き本文に連絡先付箋が追加されたメモ主体の原本。手書き情報の抽出・構造化を中心に検証する。 | AS41: 配車担当＋作成者 | AT41: 読めない手書きを推測する／積地と卸地を取り違える | AU41: 手書きの表現揺れを吸収しつつ原文を保持 | AV41: D035.jpg
A42: 36 | C42: D036 | D42: T01 | E42: 小型定型印字帳票 | AN42: 標準印字・定型帳票 | AO42: 運送依頼書 | AP42: 明瞭な印字項目の抽出・欄対応 | AQ42: 明瞭な必須情報の抽出漏れ0件、明瞭な情報の誤入力・誤分類0件。未記載は補完しない。 | AR42: 小型だが明瞭な表形式の印字帳票。明瞭な印字項目の抽出・欄対応を中心に検証する。 | AS42: 配車担当＋作成者 | AT42: 明瞭な積地・卸地・日時・数量を誤読／別欄へ誤分類する | AU42: 標準読取のベースライン | AV42: D036.jpg
A43: 37 | C43: D037 | D43: T02 | E43: 劣化FAX | AN43: FAX・スキャン劣化 | AO43: 配車依頼（FAX） | AP43: かすれ・黒つぶれ・低コントラスト箇所の扱い | AQ43: 判読できる箇所の誤読0件。判読不能箇所の勝手な確定0件。不明は要確認にする。 | AR43: 黒つぶれ・ノイズ・低コントラストが強いFAX。かすれ・黒つぶれ・低コントラスト箇所の扱いを中心に検証する。 | AS43: 配車担当＋作成者 | AT43: 潰れた電話番号や文字を推測して確定する | AU43: 画像劣化は安全側に倒す | AV43: D037.jpg
A44: 38 | C44: D038 | D44: T13 | E44: チャット／メッセージ画面＋地図 | AN44: 複合資料・添付情報 | AO44: メッセージ＋位置情報 | AP44: 本文・写真・地図・付箋・別紙等の複数情報源の統合 | AQ44: 運行に必要な追記・付箋・地図情報の見落とし0件。本文との重複・矛盾を整理し、不明な優先関係は要確認。 | AR44: メッセージ本文と地図位置情報が同一画像に含まれる複合資料。本文・写真・地図・付箋・別紙等の複数情報源の統合を中心に検証する。 | AS44: 配車担当＋作成者 | AT44: 付箋・地図・添付写真の条件を無視／別情報源の内容を誤って上書き | AU44: 複数情報源の出所と関係を保つ | AV44: D038.jpg
A45: 39 | C45: D039 | D45: T03 | E45: 手書き依頼メモ | AN45: 手書き主体 | AO45: 配車依頼メモ | AP45: 手書き情報の抽出・構造化 | AQ45: 明確に読める手書き情報の反映漏れ0件、誤読0件。判読不能は要確認にする。 | AR45: 手書きの項目列挙と注意書きから構造化する原本。手書き情報の抽出・構造化を中心に検証する。 | AS45: 配車担当＋作成者 | AT45: 読めない手書きを推測する／積地と卸地を取り違える | AU45: 手書きの表現揺れを吸収しつつ原文を保持 | AV45: D039.jpg
A46: 40 | C46: D040 | D46: T03 | E46: 手書きルートメモ | AN46: 手書き主体 | AO46: 配車ルートメモ | AP46: 手書き情報の抽出・構造化 | AQ46: 明確に読める手書き情報の反映漏れ0件、誤読0件。判読不能は要確認にする。 | AR46: 積地→卸地の矢印と荷物条件を手書きで示したメモ。手書き情報の抽出・構造化を中心に検証する。 | AS46: 配車担当＋作成者 | AT46: 読めない手書きを推測する／積地と卸地を取り違える | AU46: 手書きの表現揺れを吸収しつつ原文を保持 | AV46: D040.jpg
A47: 41 | C47: D041 | D47: T11 | E47: しわ・破れのある印字帳票 | AN47: 汚損・しわ・物理劣化 | AO47: 配送依頼書 | AP47: 汚れ・しわ・破れ・経年劣化がある原本の読取 | AQ47: 物理劣化の影響がない明瞭部分の誤読0件。欠損・汚損で読めない箇所の勝手な補完0件。 | AR47: 紙面に強いしわ・破れ・汚れがある印字帳票。汚れ・しわ・破れ・経年劣化がある原本の読取を中心に検証する。 | AS47: 配車担当＋作成者 | AT47: 汚れや折れで欠けた文字を推測して確定する | AU47: FAXノイズではなく原紙の物理劣化 | AV47: D041.jpg
A48: 42 | C48: D042 | D48: T03 | E48: 手書きメモ | AN48: 手書き主体 | AO48: 配車メモ | AP48: 手書き情報の抽出・構造化 | AQ48: 明確に読める手書き情報の反映漏れ0件、誤読0件。判読不能は要確認にする。 | AR48: 積地・卸地・荷物・車種を簡潔に手書きしたメモ。手書き情報の抽出・構造化を中心に検証する。 | AS48: 配車担当＋作成者 | AT48: 読めない手書きを推測する／積地と卸地を取り違える | AU48: 手書きの表現揺れを吸収しつつ原文を保持 | AV48: D042.jpg
A49: 43 | C49: D043 | D49: T01 | E49: FAX送信票（鮮明） | AN49: 標準印字・定型帳票 | AO49: FAX送信票／配送手配 | AP49: 明瞭な印字項目の抽出・欄対応 | AQ49: 明瞭な必須情報の抽出漏れ0件、明瞭な情報の誤入力・誤分類0件。未記載は補完しない。 | AR49: FAX形式だが判読性が高い小型定型帳票。明瞭な印字項目の抽出・欄対応を中心に検証する。 | AS49: 配車担当＋作成者 | AT49: 明瞭な積地・卸地・日時・数量を誤読／別欄へ誤分類する | AU49: 標準読取のベースライン | AV49: D043.jpg
A50: 44 | C50: D044 | D50: T06 | E50: スマホメール画面 | AN50: 曖昧日時・時間幅 | AO50: 配送依頼メール | AP50: AM/PM・午前中・頃・まで・以降・時間幅の保持 | AQ50: 日付・曜日・AM/PM誤り0件。条件語・時間幅の欠落0件。曖昧表現を具体時刻へ勝手に変換しない。 | AR50: メール本文に希望日『AM指定』があり具体時刻へ変換してはいけない。AM/PM・午前中・頃・まで・以降・時間幅の保持を中心に検証する。 | AS50: 配車担当＋作成者 | AT50: 『午前中』『PM』『9時頃』を単一時刻へ確定する | AU50: 原文条件を保持 | AV50: D044.jpg
A51: 45 | C51: D045 | D51: T11 | E51: 汚損した印字帳票 | AN51: 汚損・しわ・物理劣化 | AO51: 出荷指示書 | AP51: 汚れ・しわ・破れ・経年劣化がある原本の読取 | AQ51: 物理劣化の影響がない明瞭部分の誤読0件。欠損・汚損で読めない箇所の勝手な補完0件。 | AR51: 大きなシミ・汚れで一部背景が劣化した印字帳票。汚れ・しわ・破れ・経年劣化がある原本の読取を中心に検証する。 | AS51: 配車担当＋作成者 | AT51: 汚れや折れで欠けた文字を推測して確定する | AU51: FAXノイズではなく原紙の物理劣化 | AV51: D045.jpg
... A70: 64 | C70: D064 | D70: T12 | E70: メール本文（冷凍・温度指定） | AN70: 特殊輸送条件 | AO70: 配送依頼メール | AP70: 温度・危険物・精密品・車両制約等の重要条件保持 | AQ70: 温度、危険物区分、荷扱い禁止事項、必要車両・装備など安全・品質に関わる条件の欠落0件、意味変更0件。 | AR70: 冷凍食品、4t冷凍車、温度『-18℃設定』が明記されている。温度・危険物・精密品・車両制約等の重要条件保持を中心に検証する。 | AS70: 配車担当＋作成者 | AT70: 温度指定や危険物表示、横倒し禁止、必要装備を落とす／緩和する | AU70: 安全・品質条件を最優先で保持 | AV70: D064.jpg
A71: 65 | C71: D065 | D71: T11 | E71: 汚損した手書き帳票 | N71: =IF(COUNTA(K71:M71)=0,"",SUM(K71:M71)) | AN71: 汚損・しわ・物理劣化 | AO71: 配車依頼 | AP71: 汚れ・しわ・破れ・経年劣化がある原本の読取 | AQ71: 物理劣化の影響がない明瞭部分の誤読0件。欠損・汚損で読めない箇所の勝手な補完0件。 | AR71: 大きな水濡れ・シミがある手書き記入帳票。汚れ・しわ・破れ・経年劣化がある原本の読取を中心に検証する。 | AS71: 配車担当＋作成者 | AT71: 汚れや折れで欠けた文字を推測して確定する | AU71: FAXノイズではなく原紙の物理劣化 | AV71: D065.jpg
A72: 66 | C72: D066 | D72: T12 | E72: 小型定型印字帳票（精密機器） | AN72: 特殊輸送条件 | AO72: 運送依頼書 | AP72: 温度・危険物・精密品・車両制約等の重要条件保持 | AQ72: 温度、危険物区分、荷扱い禁止事項、必要車両・装備など安全・品質に関わる条件の欠落0件、意味変更0件。 | AR72: 精密機器、横倒厳禁・取扱注意、箱車指定等の重要条件がある。温度・危険物・精密品・車両制約等の重要条件保持を中心に検証する。 | AS72: 配車担当＋作成者 | AT72: 温度指定や危険物表示、横倒し禁止、必要装備を落とす／緩和する | AU72: 安全・品質条件を最優先で保持 | AV72: D066.jpg
A73: 67 | C73: D067 | D73: T03 | E73: 手書きメモ＋付箋 | AN73: 手書き主体 | AO73: 配車メモ | AP73: 手書き情報の抽出・構造化 | AQ73: 明確に読める手書き情報の反映漏れ0件、誤読0件。判読不能は要確認にする。 | AR73: 手書き本文に『至急対応』付箋が付いた原本。手書き情報の抽出・構造化を中心に検証する。 | AS73: 配車担当＋作成者 | AT73: 読めない手書きを推測する／積地と卸地を取り違える | AU73: 手書きの表現揺れを吸収しつつ原文を保持 | AV73: D067.jpg
A74: 68 | C74: D068 | D74: T12 | E74: 危険物表示付き印字帳票 | AN74: 特殊輸送条件 | AO74: 運送指示書 | AP74: 温度・危険物・精密品・車両制約等の重要条件保持 | AQ74: 温度、危険物区分、荷扱い禁止事項、必要車両・装備など安全・品質に関わる条件の欠落0件、意味変更0件。 | AR74: 『危険物』表示、消防法該当、ドラム缶等の安全条件がある。温度・危険物・精密品・車両制約等の重要条件保持を中心に検証する。 | AS74: 配車担当＋作成者 | AT74: 温度指定や危険物表示、横倒し禁止、必要装備を落とす／緩和する | AU74: 安全・品質条件を最優先で保持 | AV74: D068.jpg
A75: 69 | C75: D069 | D75: T07 | E75: 手書き依頼メモ＋訂正 | AN75: 訂正・追記・矛盾 | AO75: 配車依頼メモ | AP75: 訂正前後・追記・矛盾情報の優先判断 | AQ75: 明確な訂正後情報の採用漏れ0件。取消線前の値を採用しない。矛盾が残る場合は勝手に決めず要確認へ戻す。 | AR75: 積地・車種・日付時刻などに取消線と赤字変更がある。訂正前後・追記・矛盾情報の優先判断を中心に検証する。 | AS75: 配車担当＋作成者 | AT75: 訂正前の数量・時刻を採用／付箋や赤字追記を無視／矛盾する一方を勝手に採用 | AU75: 訂正の意図が不明なら人が最終判断 | AV75: D069.jpg
A76: 70 | C76: D070 | D76: T05 | E76: 複数案件一覧（印字） | AN76: 複数地点・複数案件 | AO76: 配車依頼（複数件） | AP76: 地点・案件の順序と日時・荷物の紐付け保持 | AQ76: 地点・案件の欠落0件、順序逆転0件、日時・荷物・担当の紐付け誤り0件。 | AR76: 2件の積卸・品名・数量・時刻を同一車両で扱う一覧。地点・案件の順序と日時・荷物の紐付け保持を中心に検証する。 | AS76: 配車担当 | AT76: 積地②と卸地①を逆転する／別案件の数量を混在させる | AU76: 順番や紐付けが不明なら要確認 | AV76: D070.jpg
...

Sheet 02_T01-T10判定基準
A1: T01〜T13 判定基準（画像基準）
A2: ※ シート名は既存参照との互換性維持のため「02_T01-T10判定基準」のままです。
A3: 試験ID | B3: 対象 | C3: 主な確認内容 | D3: 合格条件 | E3: 判定者 | F3: 不合格となる例 | G3: 備考
A4: T01 | B4: 標準印字・定型帳票 | C4: 明瞭な印字項目の抽出・欄対応 | D4: 明瞭な必須情報の抽出漏れ0件、明瞭な情報の誤入力・誤分類0件。未記載は補完しない。 | E4: 配車担当＋作成者 | F4: 明瞭な積地・卸地・日時・数量を誤読／別欄へ誤分類する | G4: 標準読取のベースライン
A5: T02 | B5: FAX・スキャン劣化 | C5: かすれ・黒つぶれ・低コントラスト箇所の扱い | D5: 判読できる箇所の誤読0件。判読不能箇所の勝手な確定0件。不明は要確認にする。 | E5: 配車担当＋作成者 | F5: 潰れた電話番号や文字を推測して確定する | G5: 画像劣化は安全側に倒す
A6: T03 | B6: 手書き主体 | C6: 手書き情報の抽出・構造化 | D6: 明確に読める手書き情報の反映漏れ0件、誤読0件。判読不能は要確認にする。 | E6: 配車担当＋作成者 | F6: 読めない手書きを推測する／積地と卸地を取り違える | G6: 手書きの表現揺れを吸収しつつ原文を保持
A7: T04 | B7: メール・自由文 | C7: 文章・メール本文からの項目整理 | D7: 明確な必須情報の抽出漏れ0件、積地・卸地・日時・荷物の誤分類0件。 | E7: 配車担当＋作成者 | F7: 文章中の卸地を積地欄へ入れる／担当・日時の紐付けを崩す | G7: レイアウト非依存
A8: T05 | B8: 複数地点・複数案件 | C8: 地点・案件の順序と日時・荷物の紐付け保持 | D8: 地点・案件の欠落0件、順序逆転0件、日時・荷物・担当の紐付け誤り0件。 | E8: 配車担当 | F8: 積地②と卸地①を逆転する／別案件の数量を混在させる | G8: 順番や紐付けが不明なら要確認
A9: T06 | B9: 曖昧日時・時間幅 | C9: AM/PM・午前中・頃・まで・以降・時間幅の保持 | D9: 日付・曜日・AM/PM誤り0件。条件語・時間幅の欠落0件。曖昧表現を具体時刻へ勝手に変換しない。 | E9: 配車担当＋作成者 | F9: 『午前中』『PM』『9時頃』を単一時刻へ確定する | G9: 原文条件を保持
A10: T07 | B10: 訂正・追記・矛盾 | C10: 訂正前後・追記・矛盾情報の優先判断 | D10: 明確な訂正後情報の採用漏れ0件。取消線前の値を採用しない。矛盾が残る場合は勝手に決めず要確認へ戻す。 | E10: 配車担当＋作成者 | F10: 訂正前の数量・時刻を採用／付箋や赤字追記を無視／矛盾する一方を勝手に採用 | G10: 訂正の意図が不明なら人が最終判断
A11: T08 | B11: 情報不足・部分資料 | C11: 欠落・黒塗り・補助資料のみの場合の扱い | D11: 不足情報の推測確定0件。欠落・黒塗り・未定は記載なし／要確認として扱い、補助資料から存在しない値を作らない。 | E11: 配車担当＋作成者 | F11: 未記載の卸地・連絡先・重量などを推測して入力する | G11: 不足を検知して確認へ戻す
A12: T09 | B12: 禁止情報混在 | C12: 運賃・支払・金額情報の非転記 | D12: 禁止情報誤出力0件。運行に必要な情報だけを抽出し、運賃・支払・単価等を配車指示書へ転記しない。 | E12: 配車担当＋社内ルール判定者 | F12: 運賃・受注金額・支払条件などを運送会社向け指示書へ出力する | G12: 禁止範囲は運用ルールを優先
A13: T10 | B13: 今回・過去／参考情報併記 | C13: 今回情報と過去・参考情報の優先制御 | D13: 過去・参考値による今回情報の自動上書き0件。今回欄と参考欄を混在させない。 | E13: 配車担当＋作成者 | F13: 前回担当者・数量・時刻を今回欄へ確定する | G13: 今回原本を優先し、過去情報は候補扱い
A14: T11 | B14: 汚損・しわ・物理劣化 | C14: 汚れ・しわ・破れ・経年劣化がある原本の読取 | D14: 物理劣化の影響がない明瞭部分の誤読0件。欠損・汚損で読めない箇所の勝手な補完0件。 | E14: 配車担当＋作成者 | F14: 汚れや折れで欠けた文字を推測して確定する | G14: FAXノイズではなく原紙の物理劣化
... A16: T13 | B16: 複合資料・添付情報 | C16: 本文・写真・地図・付箋・別紙等の複数情報源の統合 | D16: 運行に必要な追記・付箋・地図情報の見落とし0件。本文との重複・矛盾を整理し、不明な優先関係は要確認。 | E16: 配車担当＋作成者 | F16: 付箋・地図・添付写真の条件を無視／別情報源の内容を誤って上書き | G16: 複数情報源の出所と関係を保つ

Sheet 03_入力ルール
A1: 入力・判定ルール
A3: 項目 | B3: ルール | C3: 例 | D3: 注意
A4: 要確認 | B4: 読めない・曖昧・矛盾・不足は推測せず要確認 | C4: 電話番号の一部が潰れている→要確認 | D4: 要確認は失敗ではない
A5: 誤読 | B5: 明確に読める情報を間違えて抽出した件数 | C5: 9:00を8:00と抽出 | D5: 0件が望ましい
A6: 勝手に確定 | B6: 本来要確認の内容をAIが推測して確定した件数 | C6: 朝一→8:00 | D6: 0件を合格条件
A7: 禁止情報誤出力 | B7: 傭車先等へ出してはいけない情報を出力した件数 | C7: 受取運賃を傭車先向けへ表示 | D7: 0件を合格条件
A8: 総作業時間 | B8: AI操作＋人の確認＋修正 | C8: 2.0+3.0+1.0=6.0分 | D8: 待ち時間・電話中断は別管理が望ましい
A9: 難易度 | B9: 当初は未分類で記録し、件数蓄積後に分類 | C9: 流用有無、新規入力項目数、実測時間で分類 | D9: 先に主観で固定しない
A10: 合否 | B10: T01〜T10判定基準に従う | C10: T02で推測0件かつ不明を要確認→合格 | D10: 安全項目は1件でもNGあり
A11: 処理開始時刻 | B11: 依頼を受け、処理を開始する直前の時刻 | C11: 2026/10/02 15:30:01 | D11: 取得できない場合は推測せず『時刻取得不可』
A12: 画像読込開始／完了時刻 | B12: 画像読込開始直前と、読込・抽出・要確認判定が完了した時刻 | C12: 開始 15:30:03／完了 15:30:12 | D12: JSTで記録。内部時刻が取得不能なら推測しない
A13: 画像読込所要時間(秒) | B13: 画像読込開始時刻から画像読込完了時刻までの差 | C13: 9 | D13: 秒単位。開始・完了のどちらかが取得不能なら空欄
A14: 処理完了時刻 | B14: 01_指示書読込プロンプトの回答・判定まで含めた処理が完了する直前の時刻 | C14: 2026/10/02 15:30:15 | D14: 画像読込完了時刻やPDF出力完了時刻とは分けて記録
... A27: 結果入力 | B27: Y列 合否 | C27: 検証完了後に入力 | D27: AQ列の合格条件と実測・比較結果を確認して判定。未確認の安全項目がある場合は合格にしない。

Sheet 05_ケース別テスト対応
A1: No. | B1: ケースID | C1: 試験ID | D1: 対象 | E1: 媒体／表現 | F1: 帳票／形式 | G1: 主な確認内容 | H1: 合格条件 | I1: このケースの検証ポイント | J1: 判定者 | K1: 不合格となる例 | L1: 備考 | M1: 画像ファイル名
A2: 1 | B2: D001 | C2: T01 | D2: 標準印字・定型帳票 | E2: 定型印字帳票 | F2: 貨物配送依頼書 | G2: 明瞭な印字項目の抽出・欄対応 | H2: 明瞭な必須情報の抽出漏れ0件、明瞭な情報の誤入力・誤分類0件。未記載は補完しない。 | I2: 表形式で明瞭な標準帳票。明瞭な印字項目の抽出・欄対応を中心に検証する。 | J2: 配車担当＋作成者 | K2: 明瞭な積地・卸地・日時・数量を誤読／別欄へ誤分類する | L2: 標準読取のベースライン | M2: D001.jpg
A3: 2 | B3: D002 | C3: T02 | D3: FAX・スキャン劣化 | E3: 劣化FAX | F3: 配送依頼書（FAX） | G3: かすれ・黒つぶれ・低コントラスト箇所の扱い | H3: 判読できる箇所の誤読0件。判読不能箇所の勝手な確定0件。不明は要確認にする。 | I3: 黒つぶれ・かすれ・走査ノイズが目立つFAX。かすれ・黒つぶれ・低コントラスト箇所の扱いを中心に検証する。 | J3: 配車担当＋作成者 | K3: 潰れた電話番号や文字を推測して確定する | L3: 画像劣化は安全側に倒す | M3: D002.jpg
A4: 3 | B4: D003 | C4: T03 | D4: 手書き主体 | E4: 全手書きメモ | F4: 運送手配メモ | G4: 手書き情報の抽出・構造化 | H4: 明確に読める手書き情報の反映漏れ0件、誤読0件。判読不能は要確認にする。 | I4: 紙面全体が手書きで、吹き出し状の追記もある。手書き情報の抽出・構造化を中心に検証する。 | J4: 配車担当＋作成者 | K4: 読めない手書きを推測する／積地と卸地を取り違える | L4: 手書きの表現揺れを吸収しつつ原文を保持 | M4: D003.jpg
A5: 4 | B5: D004 | C5: T07 | D5: 訂正・追記・矛盾 | E5: メール印刷＋手書き追記 | F5: 配送依頼メール | G5: 訂正前後・追記・矛盾情報の優先判断 | H5: 明確な訂正後情報の採用漏れ0件。取消線前の値を採用しない。矛盾が残る場合は勝手に決めず要確認へ戻す。 | I5: メール本文に手書きの時刻・連絡注意等が追加されている。訂正前後・追記・矛盾情報の優先判断を中心に検証する。 | J5: 配車担当＋作成者 | K5: 訂正前の数量・時刻を採用／付箋や赤字追記を無視／矛盾する一方を勝手に採用 | L5: 訂正の意図が不明なら人が最終判断 | M5: D004.jpg
A6: 5 | B6: D005 | C6: T07 | D6: 訂正・追記・矛盾 | E6: 定型印字帳票＋手書き訂正 | F6: 運送指示書 | G6: 訂正前後・追記・矛盾情報の優先判断 | H6: 明確な訂正後情報の採用漏れ0件。取消線前の値を採用しない。矛盾が残る場合は勝手に決めず要確認へ戻す。 | I6: 積込時刻・数量などに手書き訂正が入っている。訂正前後・追記・矛盾情報の優先判断を中心に検証する。 | J6: 配車担当＋作成者 | K6: 訂正前の数量・時刻を採用／付箋や赤字追記を無視／矛盾する一方を勝手に採用 | L6: 訂正の意図が不明なら人が最終判断 | M6: D005.jpg
A7: 6 | B7: D006 | C7: T02 | D7: FAX・スキャン劣化 | E7: 劣化FAX＋手書き記入 | F7: 運送依頼書（FAX） | G7: かすれ・黒つぶれ・低コントラスト箇所の扱い | H7: 判読できる箇所の誤読0件。判読不能箇所の勝手な確定0件。不明は要確認にする。 | I7: FAXノイズが強く、手書き記入欄も混在している。かすれ・黒つぶれ・低コントラスト箇所の扱いを中心に検証する。 | J7: 配車担当＋作成者 | K7: 潰れた電話番号や文字を推測して確定する | L7: 画像劣化は安全側に倒す | M7: D006.jpg
A8: 7 | B8: D007 | C8: T05 | D8: 複数地点・複数案件 | E8: 複数地点ルート表（印字） | F8: 配送依頼書（複数地点） | G8: 地点・案件の順序と日時・荷物の紐付け保持 | H8: 地点・案件の欠落0件、順序逆転0件、日時・荷物・担当の紐付け誤り0件。 | I8: 積込2地点・荷卸2地点が順序付きで記載されている。地点・案件の順序と日時・荷物の紐付け保持を中心に検証する。 | J8: 配車担当 | K8: 積地②と卸地①を逆転する／別案件の数量を混在させる | L8: 順番や紐付けが不明なら要確認 | M8: D007.jpg
A9: 8 | B9: D008 | C9: T06 | D9: 曖昧日時・時間幅 | E9: 印字依頼文書 | F9: 輸送手配依頼文書 | G9: AM/PM・午前中・頃・まで・以降・時間幅の保持 | H9: 日付・曜日・AM/PM誤り0件。条件語・時間幅の欠落0件。曖昧表現を具体時刻へ勝手に変換しない。 | I9: 『午前9時頃』『午前中』『午後2時まで』等の幅を持つ時刻表現がある。AM/PM・午前中・頃・まで・以降・時間幅の保持を中心に検証する。 | J9: 配車担当＋作成者 | K9: 『午前中』『PM』『9時頃』を単一時刻へ確定する | L9: 原文条件を保持 | M9: D008.jpg
A10: 9 | B10: D009 | C10: T07 | D10: 訂正・追記・矛盾 | E10: 印字帳票＋大量手書き追記 | F10: 運送手配依頼書 | G10: 訂正前後・追記・矛盾情報の優先判断 | H10: 明確な訂正後情報の採用漏れ0件。取消線前の値を採用しない。矛盾が残る場合は勝手に決めず要確認へ戻す。 | I10: 多数の赤字・青字追記、地図、時刻修正が混在している。訂正前後・追記・矛盾情報の優先判断を中心に検証する。 | J10: 配車担当＋作成者 | K10: 訂正前の数量・時刻を採用／付箋や赤字追記を無視／矛盾する一方を勝手に採用 | L10: 訂正の意図が不明なら人が最終判断 | M10: D009.jpg
A11: 10 | B11: D010 | C11: T01 | D11: 標準印字・定型帳票 | E11: 定型印字帳票 | F11: 運行依頼書 | G11: 明瞭な印字項目の抽出・欄対応 | H11: 明瞭な必須情報の抽出漏れ0件、明瞭な情報の誤入力・誤分類0件。未記載は補完しない。 | I11: 明瞭な単一積地・単一納品先の標準帳票。明瞭な印字項目の抽出・欄対応を中心に検証する。 | J11: 配車担当＋作成者 | K11: 明瞭な積地・卸地・日時・数量を誤読／別欄へ誤分類する | L11: 標準読取のベースライン | M11: D010.jpg
A12: 11 | B12: D011 | C12: T01 | D12: 標準印字・定型帳票 | E12: 定型印字帳票 | F12: 運送指示書 | G12: 明瞭な印字項目の抽出・欄対応 | H12: 明瞭な必須情報の抽出漏れ0件、明瞭な情報の誤入力・誤分類0件。未記載は補完しない。 | I12: 明瞭な表形式の標準印字帳票。明瞭な印字項目の抽出・欄対応を中心に検証する。 | J12: 配車担当＋作成者 | K12: 明瞭な積地・卸地・日時・数量を誤読／別欄へ誤分類する | L12: 標準読取のベースライン | M12: D011.jpg
A13: 12 | B13: D012 | C13: T02 | D13: FAX・スキャン劣化 | E13: 劣化FAX | F13: 配送依頼書（FAX） | G13: かすれ・黒つぶれ・低コントラスト箇所の扱い | H13: 判読できる箇所の誤読0件。判読不能箇所の勝手な確定0件。不明は要確認にする。 | I13: 罫線・文字のかすれとFAXノイズがある。かすれ・黒つぶれ・低コントラスト箇所の扱いを中心に検証する。 | J13: 配車担当＋作成者 | K13: 潰れた電話番号や文字を推測して確定する | L13: 画像劣化は安全側に倒す | M13: D012.jpg
... A91: 90 | B91: D090 | C91: T13 | D91: 複合資料・添付情報 | E91: 手書きメモ＋付箋＋受付票 | F91: 配車メモ＋補助情報 | G91: 本文・写真・地図・付箋・別紙等の複数情報源の統合 | H91: 運行に必要な追記・付箋・地図情報の見落とし0件。本文との重複・矛盾を整理し、不明な優先関係は要確認。 | I91: 手書き本文に受付票と連絡付箋が重なり、複数情報源を統合する必要がある。本文・写真・地図・付箋・別紙等の複数情報源の統合を中心に検証する。 | J91: 配車担当＋作成者 | K91: 付箋・地図・添付写真の条件を無視／別情報源の内容を誤って上書き | L91: 複数情報源の出所と関係を保つ | M91: D090.jpg

Sheet 06_試験ID件数サマリー
A1: 試験ID | B1: ケース数 | C1: 対象 | D1: ケースID | F1: 集計 | G1: 値
A2: T01 | B2: =COUNTIF('01_テスト結果一覧'!$D$7:$D$96,A2) -> 16 | C2: 標準印字・定型帳票 | D2: D001、D010、D011、D021、D032、D036、D043、D047、D050、D061、D072、D073、D078、D081、D085、D087 | F2: 総ケース数 | G2: =SUM(B2:B14) -> 90
A3: T02 | B3: =COUNTIF('01_テスト結果一覧'!$D$7:$D$96,A3) -> 8 | C3: FAX・スキャン劣化 | D3: D002、D006、D012、D037、D049、D053、D062、D079 | F3: 試験ID数 | G3: =COUNTA(A2:A14) -> 13
A4: T03 | B4: =COUNTIF('01_テスト結果一覧'!$D$7:$D$96,A4) -> 14 | C4: 手書き主体 | D4: D003、D035、D039、D040、D042、D048、D054、D056、D063、D067、D071、D077、D080、D082 | F4: 変更ケース数 | G4: =COUNTIF('07_画像基準再分類_変更一覧'!$L$2:$L$91,"変更") -> 89
A5: T04 | B5: =COUNTIF('01_テスト結果一覧'!$D$7:$D$96,A5) -> 7 | C5: メール・自由文 | D5: D014、D016、D024、D034、D059、D074、D076 | F5: 維持ケース数 | G5: =COUNTIF('07_画像基準再分類_変更一覧'!$L$2:$L$91,"維持") -> 1
A6: T05 | B6: =COUNTIF('01_テスト結果一覧'!$D$7:$D$96,A6) -> 4 | C6: 複数地点・複数案件 | D6: D007、D015、D025、D070 | F6: 分類基準 | G6: 画像の実態を優先
A7: T06 | B7: =COUNTIF('01_テスト結果一覧'!$D$7:$D$96,A7) -> 9 | C7: 曖昧日時・時間幅 | D7: D008、D019、D026、D031、D033、D044、D052、D086、D088
A8: T07 | B8: =COUNTIF('01_テスト結果一覧'!$D$7:$D$96,A8) -> 9 | C8: 訂正・追記・矛盾 | D8: D004、D005、D009、D017、D018、D023、D027、D057、D069
A9: T08 | B9: =COUNTIF('01_テスト結果一覧'!$D$7:$D$96,A9) -> 3 | C9: 情報不足・部分資料 | D9: D028、D046、D083
A10: T09 | B10: =COUNTIF('01_テスト結果一覧'!$D$7:$D$96,A10) -> 3 | C10: 禁止情報混在 | D10: D013、D022、D029
A11: T10 | B11: =COUNTIF('01_テスト結果一覧'!$D$7:$D$96,A11) -> 1 | C11: 今回・過去／参考情報併記 | D11: D030
A12: T11 | B12: =COUNTIF('01_テスト結果一覧'!$D$7:$D$96,A12) -> 6 | C12: 汚損・しわ・物理劣化 | D12: D041、D045、D051、D060、D065、D084
A13: T12 | B13: =COUNTIF('01_テスト結果一覧'!$D$7:$D$96,A13) -> 6 | C13: 特殊輸送条件 | D13: D055、D064、D066、D068、D075、D089
A14: T13 | B14: =COUNTIF('01_テスト結果一覧'!$D$7:$D$96,A14) -> 4 | C14: 複合資料・添付情報 | D14: D020、D038、D058、D090

Sheet 00_使い方
A1: 配車指示書PoC 一括実行セット
A2: 目的 | B2: 添付回数を減らし、原本読込 → 指示書作成 → PDF出力 → テスト結果記録までを1回の指示で実行するためのマスターブックです。
A3: 毎回必要なもの | B3: ①このExcel ②対象のテスト画像1枚（D001.jpg等）。同じチャット内に全90件ZIPを一度添付済みなら、その後はケースID指定だけで進められます。
A4: ユーザーの指示例 | B4: D001を一括テストしてください
A5: AIが参照するシート | B5: Sheet1＝配車指示書テンプレート／00_PoC一括実行＝実行ルール／01_テスト結果一覧＝記録先／02_T01-T10判定基準＝画像基準で再設計したT01〜T13合否基準／05_ケース別テスト対応＝画像実態に基づくケース設定／07_画像基準再分類_変更一覧＝旧→新の対応表
A6: 重要 | B6: Sheet1は原本テンプレートとして保持し、直接上書きしない。生成する指示書は別ファイルとして出力する。
A7: 結果一覧 | B7: ケースIDが一致する行だけ更新する。D/Eおよび判定基準列は、画像実態に基づき再分類済みの05_ケース別テスト対応を参照する。未測定は0にしない。人が判断すべき項目は空欄または要確認のまま残す。
A8: 禁止情報 | B8: 荷主ヘッダー・荷主住所・荷主FAX・荷主側担当者・運賃・売上・仕入・支払・単価等は、傭車先向け配車指示書へ転記しない。
A9: おすすめ運用 | B9: 最初にこのExcelとD001-D090画像ZIPを1回だけ添付し、以後は『D001を一括テスト』『次はD002』のようにケースIDだけ指定する。

Sheet 00_PoC一括実行
A1: 00_PoC一括実行プロンプト
A2: 【目的】
A3: 対象ケース1件について、原本画像の読込、構造化、配車指示書Excel/PDF生成、原本との比較評価、テスト結果一覧への記録を連続して実行してください。
A5: 【入力】
A6: - このExcelブック
A7: - 対象ケース画像（D001.jpg等）。同じチャット内にD001-D090画像ZIPが既にある場合は、指定ケースIDの画像をZIPから使用してよい。
A8: - ユーザーが指定したケースID
A10: 【最初に行うこと】
A11: 1. ケースIDを確認する。
A12: 2. 「05_ケース別テスト対応」で同じケースIDの行を確認し、画像実態に基づき再分類済みの試験ID、対象、媒体／表現、帳票／形式、主な確認内容、合格条件、このケースの検証ポイントを取得する。
A13: 3. ケースIDが見つからない場合は処理を止め、『対象ケースなし』と報告する。
A14: 4. 他ケースの情報を混ぜない。過去ケースの値を今回へ流用しない。
... A164: - 作成したファイルへのリンク

Sheet 07_画像基準再分類_変更一覧
A1: No. | B1: ケースID | C1: 画像ファイル名 | D1: 旧試験ID | E1: 旧原本種別 | F1: 新試験ID | G1: 新対象 | H1: 新原本種別 | I1: 変更理由／画像上の根拠 | J1: 新主な確認内容 | K1: 新合格条件 | L1: 変更判定
A2: 1 | B2: D001 | C2: D001.jpg | D2: T01 | E2: 一般印字 | F2: T01 | G2: 標準印字・定型帳票 | H2: 定型印字帳票 | I2: 表形式で明瞭な標準帳票 | J2: 明瞭な印字項目の抽出・欄対応 | K2: 明瞭な必須情報の抽出漏れ0件、明瞭な情報の誤入力・誤分類0件。未記載は補完しない。 | L2: =IF(AND(D2=F2,E2=H2),"維持","変更") -> 変更
A3: 2 | B3: D002 | C3: D002.jpg | D3: T02 | E3: 劣化FAX | F3: T02 | G3: FAX・スキャン劣化 | H3: 劣化FAX | I3: 黒つぶれ・かすれ・走査ノイズが目立つFAX | J3: かすれ・黒つぶれ・低コントラスト箇所の扱い | K3: 判読できる箇所の誤読0件。判読不能箇所の勝手な確定0件。不明は要確認にする。 | L3: =IF(AND(D3=F3,E3=H3),"維持","変更") -> 維持
A4: 3 | B4: D003 | C4: D003.jpg | D4: T03 | E4: 全手書き | F4: T03 | G4: 手書き主体 | H4: 全手書きメモ | I4: 紙面全体が手書きで、吹き出し状の追記もある | J4: 手書き情報の抽出・構造化 | K4: 明確に読める手書き情報の反映漏れ0件、誤読0件。判読不能は要確認にする。 | L4: =IF(AND(D4=F4,E4=H4),"維持","変更") -> 変更
A5: 4 | B5: D004 | C5: D004.jpg | D5: T04 | E5: メール | F5: T07 | G5: 訂正・追記・矛盾 | H5: メール印刷＋手書き追記 | I5: メール本文に手書きの時刻・連絡注意等が追加されている | J5: 訂正前後・追記・矛盾情報の優先判断 | K5: 明確な訂正後情報の採用漏れ0件。取消線前の値を採用しない。矛盾が残る場合は勝手に決めず要確認へ戻す。 | L5: =IF(AND(D5=F5,E5=H5),"維持","変更") -> 変更
A6: 5 | B6: D005 | C6: D005.jpg | D6: T05 | E6: 複数地点帳票 | F6: T07 | G6: 訂正・追記・矛盾 | H6: 定型印字帳票＋手書き訂正 | I6: 積込時刻・数量などに手書き訂正が入っている | J6: 訂正前後・追記・矛盾情報の優先判断 | K6: 明確な訂正後情報の採用漏れ0件。取消線前の値を採用しない。矛盾が残る場合は勝手に決めず要確認へ戻す。 | L6: =IF(AND(D6=F6,E6=H6),"維持","変更") -> 変更
A7: 6 | B7: D006 | C7: D006.jpg | D7: T06 | E7: FAX＋手書き追記 | F7: T02 | G7: FAX・スキャン劣化 | H7: 劣化FAX＋手書き記入 | I7: FAXノイズが強く、手書き記入欄も混在している | J7: かすれ・黒つぶれ・低コントラスト箇所の扱い | K7: 判読できる箇所の誤読0件。判読不能箇所の勝手な確定0件。不明は要確認にする。 | L7: =IF(AND(D7=F7,E7=H7),"維持","変更") -> 変更
A8: 7 | B8: D007 | C8: D007.jpg | D8: T07 | E8: 印字＋付箋・追記 | F8: T05 | G8: 複数地点・複数案件 | H8: 複数地点ルート表（印字） | I8: 積込2地点・荷卸2地点が順序付きで記載されている | J8: 地点・案件の順序と日時・荷物の紐付け保持 | K8: 地点・案件の欠落0件、順序逆転0件、日時・荷物・担当の紐付け誤り0件。 | L8: =IF(AND(D8=F8,E8=H8),"維持","変更") -> 変更
A9: 8 | B9: D008 | C9: D008.jpg | D9: T08 | E9: 手書き＋未確定 | F9: T06 | G9: 曖昧日時・時間幅 | H9: 印字依頼文書 | I9: 『午前9時頃』『午前中』『午後2時まで』等の幅を持つ時刻表現がある | J9: AM/PM・午前中・頃・まで・以降・時間幅の保持 | K9: 日付・曜日・AM/PM誤り0件。条件語・時間幅の欠落0件。曖昧表現を具体時刻へ勝手に変換しない。 | L9: =IF(AND(D9=F9,E9=H9),"維持","変更") -> 変更
A10: 9 | B10: D009 | C10: D009.jpg | D10: T09 | E10: FAX帳票 | F10: T07 | G10: 訂正・追記・矛盾 | H10: 印字帳票＋大量手書き追記 | I10: 多数の赤字・青字追記、地図、時刻修正が混在している | J10: 訂正前後・追記・矛盾情報の優先判断 | K10: 明確な訂正後情報の採用漏れ0件。取消線前の値を採用しない。矛盾が残る場合は勝手に決めず要確認へ戻す。 | L10: =IF(AND(D10=F10,E10=H10),"維持","変更") -> 変更
A11: 10 | B11: D010 | C11: D010.jpg | D11: T10 | E11: 今回/前回比較 | F11: T01 | G11: 標準印字・定型帳票 | H11: 定型印字帳票 | I11: 明瞭な単一積地・単一納品先の標準帳票 | J11: 明瞭な印字項目の抽出・欄対応 | K11: 明瞭な必須情報の抽出漏れ0件、明瞭な情報の誤入力・誤分類0件。未記載は補完しない。 | L11: =IF(AND(D11=F11,E11=H11),"維持","変更") -> 変更
A12: 11 | B12: D011 | C12: D011.jpg | D12: T01 | E12: 一般印字 | F12: T01 | G12: 標準印字・定型帳票 | H12: 定型印字帳票 | I12: 明瞭な表形式の標準印字帳票 | J12: 明瞭な印字項目の抽出・欄対応 | K12: 明瞭な必須情報の抽出漏れ0件、明瞭な情報の誤入力・誤分類0件。未記載は補完しない。 | L12: =IF(AND(D12=F12,E12=H12),"維持","変更") -> 変更
A13: 12 | B13: D012 | C13: D012.jpg | D13: T02 | E13: FAX | F13: T02 | G13: FAX・スキャン劣化 | H13: 劣化FAX | I13: 罫線・文字のかすれとFAXノイズがある | J13: かすれ・黒つぶれ・低コントラスト箇所の扱い | K13: 判読できる箇所の誤読0件。判読不能箇所の勝手な確定0件。不明は要確認にする。 | L13: =IF(AND(D13=F13,E13=H13),"維持","変更") -> 変更
... A91: 90 | B91: D090 | C91: D090.jpg | D91: T10 | E91: 過去比較票 | F91: T13 | G91: 複合資料・添付情報 | H91: 手書きメモ＋付箋＋受付票 | I91: 手書き本文に受付票と連絡付箋が重なり、複数情報源を統合する必要がある | J91: 本文・写真・地図・付箋・別紙等の複数情報源の統合 | K91: 運行に必要な追記・付箋・地図情報の見落とし0件。本文との重複・矛盾を整理し、不明な優先関係は要確認。 | L91: =IF(AND(D91=F91,E91=H91),"維持","変更") -> 変更
